Workbook
Name list_project: 목록!$B$3:$B$3
Name list_exec: 목록!$C$3:$C$5
Name list_state: 목록!$D$3:$D$7
Name list_status: 목록!$E$3:$E$7
Name list_priority: 목록!$F$3:$F$5
Name list_frequency: 목록!$G$3:$G$6
Name list_version: 목록!$H$3:$H$6
Name list_resolution: 목록!$I$3:$I$10
Name list_env: 목록!$J$3:$J$3
Name list_label: 목록!$K$3:$K$12
Name list_reporter: 목록!$L$3:$L$3
Name list_assignee: 목록!$M$3:$M$3
Name list_sprint: 목록!$N$3:$N$4

Sheet Test Case
B2: qa-lab-miyonchat-tree-v1.13 | F2: miyonchat TC
B3: No | C3: 1-Depth | D3: 2-Depth | E3: 3-Depth | F3: Pre-Condition | G3: TN | H3: Test-Step | I3: Expected-Result | J3: 실행 주체 | K3: Priority | L3: Total Result | M3: Result | N3: Issue No. | O3: Comment | P3: Note | Q3: TC ID | R3: 검증유형 | S3: 상태
L4: Web | M4: Web
B5: OS | N5: ※ 노란색 셀은 실행 단계에서 채워집니다 — 환경 정보 / Result / Issue No. / Comment ※ 수행 전 참고사항은 전부 Note에 있습니다 — 설계 데이터는 노란 칸에 두지 않습니다
B6: 단말 | M6: Chrome
B7: 버전
B8: 작업자 이름
B9: 작업 시작일
B10: =ROW()-9 | C10: 웹 진입 | D10: 진입 분기 | E10: 미로그인 첫 진입 | F10: 미로그인 상태 | G10: 1 | H10: SUT 주소 진입한다 | I10: 로그인 화면 없이 홈 화면 노출된다 | J10: 공통 | K10: High | L10: =IF(COUNTIF(M10:M10,"Fail")>0,"Fail",IF(COUNTIF(M10:M10,"Blocked")>0,"Blocked",IF(COUNTIF(M10:M10,"NI")>0,"NI",IF(COUNTIF(M10:M10,"Pass")>0,"Pass","")))) | P10: 상태는 디버그 콘솔 상태 스위처 「미로그인」으로 만들고 [저장]합니다. 미로그인 열람 범위의 정본은 system-spec §1-1입니다 | Q10: TC-ENT-001 | R10: 결정적 | S10: 미로그인
B11: =ROW()-9 | C11: 웹 진입 | D11: 진입 분기 | E11: 미로그인 첫 진입 | G11: 2 | H11: 상단 바 확인한다 | I11: 재화 잔액 노출되지 않는다 | J11: 공통 | K11: High | L11: =IF(COUNTIF(M11:M11,"Fail")>0,"Fail",IF(COUNTIF(M11:M11,"Blocked")>0,"Blocked",IF(COUNTIF(M11:M11,"NI")>0,"NI",IF(COUNTIF(M11:M11,"Pass")>0,"Pass","")))) | Q11: TC-ENT-001 | R11: 결정적 | S11: 미로그인
B12: =ROW()-9 | C12: 웹 진입 | D12: 진입 분기 | E12: 미로그인 첫 진입 | I12: 간편 프로필 자리에 로그인 버튼 노출된다 | J12: 공통 | K12: High | L12: =IF(COUNTIF(M12:M12,"Fail")>0,"Fail",IF(COUNTIF(M12:M12,"Blocked")>0,"Blocked",IF(COUNTIF(M12:M12,"NI")>0,"NI",IF(COUNTIF(M12:M12,"Pass")>0,"Pass","")))) | Q12: TC-ENT-001 | R12: 결정적 | S12: 미로그인
B13: =ROW()-9 | C13: 웹 진입 | D13: 진입 분기 | E13: 로그인 상태 진입 분기 | F13: 계정 A(성인 인증)로 로그인한 상태 | G13: 1 | H13: SUT 주소 재진입한다 | I13: 로그인 화면 없이 홈 화면 노출된다 | J13: 공통 | K13: Medium | L13: =IF(COUNTIF(M13:M13,"Fail")>0,"Fail",IF(COUNTIF(M13:M13,"Blocked")>0,"Blocked",IF(COUNTIF(M13:M13,"NI")>0,"NI",IF(COUNTIF(M13:M13,"Pass")>0,"Pass","")))) | P13: 상태 스위처 「로그인 (성인 인증)」으로 만듭니다. 이 케이스는 상태에 따른 화면 분기를 보는 것이고, 새로고침을 견디는지는 TC-ENT-011이 따로 봅니다 | Q13: TC-ENT-002 | R13: 결정적 | S13: 성인 인증
B14: =ROW()-9 | C14: 웹 진입 | D14: 진입 분기 | E14: 로그인 상태 진입 분기 | G14: 2 | H14: 상단 바 확인한다 | I14: 재화 잔액 노출된다 | J14: 공통 | K14: Medium | L14: =IF(COUNTIF(M14:M14,"Fail")>0,"Fail",IF(COUNTIF(M14:M14,"Blocked")>0,"Blocked",IF(COUNTIF(M14:M14,"NI")>0,"NI",IF(COUNTIF(M14:M14,"Pass")>0,"Pass","")))) | Q14: TC-ENT-002 | R14: 결정적 | S14: 성인 인증
B15: =ROW()-9 | C15: 웹 진입 | D15: 진입 분기 | E15: 로그인 상태 진입 분기 | I15: 간편 프로필 노출된다 | J15: 공통 | K15: Medium | L15: =IF(COUNTIF(M15:M15,"Fail")>0,"Fail",IF(COUNTIF(M15:M15,"Blocked")>0,"Blocked",IF(COUNTIF(M15:M15,"NI")>0,"NI",IF(COUNTIF(M15:M15,"Pass")>0,"Pass","")))) | Q15: TC-ENT-002 | R15: 결정적 | S15: 성인 인증
B16: =ROW()-9 | C16: 웹 진입 | D16: 진입 분기 | E16: 세션 만료 후 재진입 | F16: 계정 A로 로그인한 뒤 세션이 만료된 상태 | G16: 1 | H16: SUT 주소 재진입한다 | I16: 만료 안내 모달 노출된다 | J16: 공통 | K16: High | L16: =IF(COUNTIF(M16:M16,"Fail")>0,"Fail",IF(COUNTIF(M16:M16,"Blocked")>0,"Blocked",IF(COUNTIF(M16:M16,"NI")>0,"NI",IF(COUNTIF(M16:M16,"Pass")>0,"Pass","")))) | P16: 만료는 상태 스위처 「세션 만료」로 만듭니다. 모달을 닫으면 미로그인이 되므로 만료 상태에서의 동작 차단은 TC-ENT-004가 대화방에서 봅니다 | Q16: TC-ENT-003 | R16: 결정적 | S16: 세션 만료
B17: =ROW()-9 | C17: 웹 진입 | D17: 진입 분기 | E17: 세션 만료 후 재진입 | G17: 2 | H17: 만료 안내 확인한다 | I17: 미로그인 상태의 홈 화면으로 복귀된다 | J17: 공통 | K17: High | L17: =IF(COUNTIF(M17:M17,"Fail")>0,"Fail",IF(COUNTIF(M17:M17,"Blocked")>0,"Blocked",IF(COUNTIF(M17:M17,"NI")>0,"NI",IF(COUNTIF(M17:M17,"Pass")>0,"Pass","")))) | Q17: TC-ENT-003 | R17: 결정적 | S17: 세션 만료
B18: =ROW()-9 | C18: 웹 진입 | D18: 진입 분기 | E18: 세션 만료 후 재진입 | G18: 3 | H18: 상단 바 확인한다 | I18: 재화 잔액 노출되지 않는다 | J18: 공통 | K18: High | L18: =IF(COUNTIF(M18:M18,"Fail")>0,"Fail",IF(COUNTIF(M18:M18,"Blocked")>0,"Blocked",IF(COUNTIF(M18:M18,"NI")>0,"NI",IF(COUNTIF(M18:M18,"Pass")>0,"Pass","")))) | Q18: TC-ENT-003 | R18: 결정적 | S18: 세션 만료
B19: =ROW()-9 | C19: 웹 진입 | D19: 진입 분기 | E19: 세션 만료 후 재진입 | I19: 간편 프로필 자리에 로그인 버튼 노출된다 | J19: 공통 | K19: High | L19: =IF(COUNTIF(M19:M19,"Fail")>0,"Fail",IF(COUNTIF(M19:M19,"Blocked")>0,"Blocked",IF(COUNTIF(M19:M19,"NI")>0,"NI",IF(COUNTIF(M19:M19,"Pass")>0,"Pass","")))) | Q19: TC-ENT-003 | R19: 결정적 | S19: 세션 만료
B20: =ROW()-9 | C20: 웹 진입 | D20: 주소 직접 진입 | E20: 로그인 상태 로그인 필요 화면 직접 진입 | F20: 계정 A로 로그인한 상태 | G20: 1 | H20: MY 탭 주소로 새로 진입한다 | I20: 로그인 화면 없이 MY 탭 노출된다 | J20: 공통 | K20: Medium | L20: =IF(COUNTIF(M20:M20,"Fail")>0,"Fail",IF(COUNTIF(M20:M20,"Blocked")>0,"Blocked",IF(COUNTIF(M20:M20,"NI")>0,"NI",IF(COUNTIF(M20:M20,"Pass")>0,"Pass","")))) | P20: 주소 끝에 `?screen=s6`을 붙입니다. 세션 지속으로 계정 스코프가 복원되므로 가드가 통과시킵니다 — 복원이 가드보다 늦으면 로그인 상태인데도 튕겨 나갑니다(§1-3) | Q20: TC-ENT-005 | R20: 결정적 | S20: 성인 인증
B21: =ROW()-9 | C21: 웹 진입 | D21: 주소 직접 진입 | E21: 로그인 필요 화면 차단과 로그인 후 복귀 | F21: 미로그인 상태 | G21: 1 | H21: 대화방 주소로 직접 진입한다 | I21: 대화방 노출되지 않는다 | J21: 공통 | K21: High | L21: =IF(COUNTIF(M21:M21,"Fail")>0,"Fail",IF(COUNTIF(M21:M21,"Blocked")>0,"Blocked",IF(COUNTIF(M21:M21,"NI")>0,"NI",IF(COUNTIF(M21:M21,"Pass")>0,"Pass","")))) | P21: 주소 끝에 `?screen=s4`를 붙입니다. 뒤에 깔 화면이 없는 경우라 모달이 아니라 로그인 화면이 뜨는 자리입니다(system-spec §1-1) | Q21: TC-GAT-001 | R21: 금칙 | S21: 미로그인
B22: =ROW()-9 | C22: 웹 진입 | D22: 주소 직접 진입 | E22: 로그인 필요 화면 차단과 로그인 후 복귀 | I22: 로그인 모달이 아니라 로그인 화면 노출된다 | J22: 공통 | K22: High | L22: =IF(COUNTIF(M22:M22,"Fail")>0,"Fail",IF(COUNTIF(M22:M22,"Blocked")>0,"Blocked",IF(COUNTIF(M22:M22,"NI")>0,"NI",IF(COUNTIF(M22:M22,"Pass")>0,"Pass","")))) | Q22: TC-GAT-001 | R22: 금칙 | S22: 미로그인
B23: =ROW()-9 | C23: 웹 진입 | D23: 주소 직접 진입 | E23: 로그인 필요 화면 차단과 로그인 후 복귀 | G23: 2 | H23: 로그인 화면에서 계정 A 선택한다 | I23: 원래 열려던 대화방으로 복귀된다 | J23: 공통 | K23: High | L23: =IF(COUNTIF(M23:M23,"Fail")>0,"Fail",IF(COUNTIF(M23:M23,"Blocked")>0,"Blocked",IF(COUNTIF(M23:M23,"NI")>0,"NI",IF(COUNTIF(M23:M23,"Pass")>0,"Pass","")))) | Q23: TC-GAT-001 | R23: 금칙 | S23: 미로그인
B24: =ROW()-9 | C24: 웹 진입 | D24: 주소 직접 진입 | E24: 채팅 탭 차단 | F24: 미로그인 상태 | G24: 1 | H24: 채팅 탭 주소로 직접 진입한다 | I24: 채팅 탭 노출되지 않는다 | J24: 공통 | K24: High | L24: =IF(COUNTIF(M24:M24,"Fail")>0,"Fail",IF(COUNTIF(M24:M24,"Blocked")>0,"Blocked",IF(COUNTIF(M24:M24,"NI")>0,"NI",IF(COUNTIF(M24:M24,"Pass")>0,"Pass","")))) | P24: 주소 끝에 `?screen=s5`를 붙입니다. 로그인 필요 화면마다 케이스를 나눈 것은 하나만 뚫렸을 때 어느 화면인지 TC ID로 읽히게 하기 위해서입니다 | Q24: TC-GAT-002 | R24: 금칙 | S24: 미로그인
B25: =ROW()-9 | C25: 웹 진입 | D25: 주소 직접 진입 | E25: 채팅 탭 차단 | I25: 로그인 화면 노출된다 | J25: 공통 | K25: High | L25: =IF(COUNTIF(M25:M25,"Fail")>0,"Fail",IF(COUNTIF(M25:M25,"Blocked")>0,"Blocked",IF(COUNTIF(M25:M25,"NI")>0,"NI",IF(COUNTIF(M25:M25,"Pass")>0,"Pass","")))) | Q25: TC-GAT-002 | R25: 금칙 | S25: 미로그인
B26: =ROW()-9 | C26: 웹 진입 | D26: 주소 직접 진입 | E26: MY 탭 차단 | F26: 미로그인 상태 | G26: 1 | H26: MY 탭 주소로 직접 진입한다 | I26: MY 탭 노출되지 않는다 | J26: 공통 | K26: High | L26: =IF(COUNTIF(M26:M26,"Fail")>0,"Fail",IF(COUNTIF(M26:M26,"Blocked")>0,"Blocked",IF(COUNTIF(M26:M26,"NI")>0,"NI",IF(COUNTIF(M26:M26,"Pass")>0,"Pass","")))) | P26: 주소 끝에 `?screen=s6`을 붙입니다. 로그인 상태에서 같은 주소가 열리는 것은 TC-ENT-005가 봅니다 | Q26: TC-GAT-003 | R26: 금칙 | S26: 미로그인
B27: =ROW()-9 | C27: 웹 진입 | D27: 주소 직접 진입 | E27: MY 탭 차단 | I27: 로그인 화면 노출된다 | J27: 공통 | K27: High | L27: =IF(COUNTIF(M27:M27,"Fail")>0,"Fail",IF(COUNTIF(M27:M27,"Blocked")>0,"Blocked",IF(COUNTIF(M27:M27,"NI")>0,"NI",IF(COUNTIF(M27:M27,"Pass")>0,"Pass","")))) | Q27: TC-GAT-003 | R27: 금칙 | S27: 미로그인
B28: =ROW()-9 | C28: 웹 진입 | D28: 주소 직접 진입 | E28: 내 작품 탭 차단 | F28: 미로그인 상태 | G28: 1 | H28: 내 작품 탭 주소로 직접 진입한다 | I28: 내 작품 탭 노출되지 않는다 | J28: 공통 | K28: High | L28: =IF(COUNTIF(M28:M28,"Fail")>0,"Fail",IF(COUNTIF(M28:M28,"Blocked")>0,"Blocked",IF(COUNTIF(M28:M28,"NI")>0,"NI",IF(COUNTIF(M28:M28,"Pass")>0,"Pass","")))) | P28: 주소 끝에 `?screen=s8`을 붙입니다. 내 작품 탭은 스텁이지만 로그인 필요 화면이라 차단은 걸립니다 | Q28: TC-GAT-004 | R28: 금칙 | S28: 미로그인
B29: =ROW()-9 | C29: 웹 진입 | D29: 주소 직접 진입 | E29: 내 작품 탭 차단 | I29: 로그인 화면 노출된다 | J29: 공통 | K29: High | L29: =IF(COUNTIF(M29:M29,"Fail")>0,"Fail",IF(COUNTIF(M29:M29,"Blocked")>0,"Blocked",IF(COUNTIF(M29:M29,"NI")>0,"NI",IF(COUNTIF(M29:M29,"Pass")>0,"Pass","")))) | Q29: TC-GAT-004 | R29: 금칙 | S29: 미로그인
B30: =ROW()-9 | C30: 웹 진입 | D30: 주소 직접 진입 | E30: 홈 화면 통과 | F30: 미로그인 상태 | G30: 1 | H30: 홈 화면 주소로 직접 진입한다 | I30: 로그인 화면 없이 홈 화면 노출된다 | J30: 공통 | K30: Medium | L30: =IF(COUNTIF(M30:M30,"Fail")>0,"Fail",IF(COUNTIF(M30:M30,"Blocked")>0,"Blocked",IF(COUNTIF(M30:M30,"NI")>0,"NI",IF(COUNTIF(M30:M30,"Pass")>0,"Pass","")))) | P30: 주소 끝에 `?screen=s2`를 붙입니다. 차단이 미로그인 열람 화면까지 과하게 걸리지 않는지를 보는 자리라 위 차단 케이스들과 함께 읽습니다 | Q30: TC-GAT-005 | R30: 결정적 | S30: 미로그인
B31: =ROW()-9 | C31: 웹 진입 | D31: 주소 직접 진입 | E31: 커뮤니티 탭 통과 | F31: 미로그인 상태 | G31: 1 | H31: 커뮤니티 탭 주소로 직접 진입한다 | I31: 로그인 화면 없이 커뮤니티 탭 노출된다 | J31: 공통 | K31: Medium | L31: =IF(COUNTIF(M31:M31,"Fail")>0,"Fail",IF(COUNTIF(M31:M31,"Blocked")>0,"Blocked",IF(COUNTIF(M31:M31,"NI")>0,"NI",IF(COUNTIF(M31:M31,"Pass")>0,"Pass","")))) | P31: 주소 끝에 `?screen=s7`을 붙입니다. 커뮤니티 탭은 전시용 정적이지만 미로그인 열람 화면이라 통과합니다 | Q31: TC-GAT-006 | R31: 결정적 | S31: 미로그인
B32: =ROW()-9 | C32: 웹 진입 | D32: 주소 직접 진입 | E32: 만료 상태 보호 화면 직접 진입 | F32: 계정 A로 로그인한 뒤 세션이 만료된 상태 | G32: 1 | H32: MY 탭 주소로 직접 진입한다 | I32: MY 탭 노출되지 않는다 | J32: 공통 | K32: High | L32: =IF(COUNTIF(M32:M32,"Fail")>0,"Fail",IF(COUNTIF(M32:M32,"Blocked")>0,"Blocked",IF(COUNTIF(M32:M32,"NI")>0,"NI",IF(COUNTIF(M32:M32,"Pass")>0,"Pass","")))) | P32: 구현의 판정은 로그인 여부 하나라 만료도 미로그인과 같은 차단을 받습니다. 주소는 `?screen=s6`이며 만료는 상태 스위처로 만듭니다 | Q32: TC-GAT-011 | R32: 금칙 | S32: 세션 만료
B33: =ROW()-9 | C33: 웹 진입 | D33: 주소 직접 진입 | E33: 만료 상태 보호 화면 직접 진입 | I33: 로그인 화면 노출된다 | J33: 공통 | K33: High | L33: =IF(COUNTIF(M33:M33,"Fail")>0,"Fail",IF(COUNTIF(M33:M33,"Blocked")>0,"Blocked",IF(COUNTIF(M33:M33,"NI")>0,"NI",IF(COUNTIF(M33:M33,"Pass")>0,"Pass","")))) | Q33: TC-GAT-011 | R33: 금칙 | S33: 세션 만료
B34: =ROW()-9 | C34: 웹 진입 | D34: 진입 분기 | E34: 새로고침 후 세션 지속 | F34: 계정 A로 로그인하고 재화·프로필을 남긴 상태 | G34: 1 | H34: 브라우저를 새로고침한다 | I34: 로그인 화면 없이 홈 화면 노출된다 | J34: 공통 | K34: High | L34: =IF(COUNTIF(M34:M34,"Fail")>0,"Fail",IF(COUNTIF(M34:M34,"Blocked")>0,"Blocked",IF(COUNTIF(M34:M34,"NI")>0,"NI",IF(COUNTIF(M34:M34,"Pass")>0,"Pass","")))) | P34: 계정 스코프만 저장합니다 — 시트 데이터는 테스트 조건이라 저장하지 않고, 화면 보기 상태도 담지 않아 새로고침하면 홈에서 시작합니다(§1-3) | Q34: TC-ENT-011 | R34: 결정적 | S34: 성인 인증
B35: =ROW()-9 | C35: 웹 진입 | D35: 진입 분기 | E35: 새로고침 후 세션 지속 | G35: 2 | H35: 상단 바와 계정 데이터를 확인한다 | I35: 로그인 상태가 유지된다 | J35: 공통 | K35: High | L35: =IF(COUNTIF(M35:M35,"Fail")>0,"Fail",IF(COUNTIF(M35:M35,"Blocked")>0,"Blocked",IF(COUNTIF(M35:M35,"NI")>0,"NI",IF(COUNTIF(M35:M35,"Pass")>0,"Pass","")))) | Q35: TC-ENT-011 | R35: 결정적 | S35: 성인 인증
B36: =ROW()-9 | C36: 웹 진입 | D36: 진입 분기 | E36: 새로고침 후 세션 지속 | I36: 재화·프로필이 복원된다 | J36: 공통 | K36: High | L36: =IF(COUNTIF(M36:M36,"Fail")>0,"Fail",IF(COUNTIF(M36:M36,"Blocked")>0,"Blocked",IF(COUNTIF(M36:M36,"NI")>0,"NI",IF(COUNTIF(M36:M36,"Pass")>0,"Pass","")))) | Q36: TC-ENT-011 | R36: 결정적 | S36: 성인 인증
B37: =ROW()-9 | C37: 웹 진입 | D37: 진입 분기 | E37: 시트 데이터는 지속되지 않음 | F37: 계정 A로 로그인하고 디버그 콘솔에서 기준일을 옮긴 상태 | G37: 1 | H37: 브라우저를 새로고침한다 | I37: 로그인 상태가 유지된다 | J37: 자동화 전용 | K37: High | L37: =IF(COUNTIF(M37:M37,"Fail")>0,"Fail",IF(COUNTIF(M37:M37,"Blocked")>0,"Blocked",IF(COUNTIF(M37:M37,"NI")>0,"NI",IF(COUNTIF(M37:M37,"Pass")>0,"Pass","")))) | P37: 시트 데이터가 남으면 앞사람이 만든 조건 위에서 다음 테스트가 돌아 무엇을 전제로 통과했는지 알 수 없게 됩니다. 화면에 드러나지 않는 경계라 상태 훅으로 확인합니다 | Q37: TC-ENT-012 | R37: 금칙 | S37: 성인 인증
B38: =ROW()-9 | C38: 웹 진입 | D38: 진입 분기 | E38: 시트 데이터는 지속되지 않음 | G38: 2 | H38: 기준일을 확인한다 | I38: 기준일이 초기값으로 돌아간다 | J38: 자동화 전용 | K38: High | L38: =IF(COUNTIF(M38:M38,"Fail")>0,"Fail",IF(COUNTIF(M38:M38,"Blocked")>0,"Blocked",IF(COUNTIF(M38:M38,"NI")>0,"NI",IF(COUNTIF(M38:M38,"Pass")>0,"Pass","")))) | Q38: TC-ENT-012 | R38: 금칙 | S38: 성인 인증
B39: =ROW()-9 | C39: 전역 셸 | D39: 상단 바 | E39: 로고로 홈 복귀 | F39: 계정 A로 로그인해 캐릭터 페이지를 연 상태 | G39: 1 | H39: 상단 바 로고 선택한다 | I39: 홈 화면 노출된다 | J39: 공통 | K39: Low | L39: =IF(COUNTIF(M39:M39,"Fail")>0,"Fail",IF(COUNTIF(M39:M39,"Blocked")>0,"Blocked",IF(COUNTIF(M39:M39,"NI")>0,"NI",IF(COUNTIF(M39:M39,"Pass")>0,"Pass","")))) | P39: 홈이 아닌 화면에서 눌렀을 때 복귀하는지를 봅니다. 홈에서 다시 누를 때의 동작은 TC-DSC-002가 맡습니다 | Q39: TC-DSC-001 | R39: 결정적 | S39: 성인 인증
B40: =ROW()-9 | C40: 전역 셸 | D40: 상단 바 | E40: 홈에서 로고 재선택 | F40: 계정 A로 로그인해 홈 화면을 아래로 스크롤한 상태 | G40: 1 | H40: 상단 바 로고 선택한다 | I40: 홈 화면 유지된다 | J40: 공통 | K40: Low | L40: =IF(COUNTIF(M40:M40,"Fail")>0,"Fail",IF(COUNTIF(M40:M40,"Blocked")>0,"Blocked",IF(COUNTIF(M40:M40,"NI")>0,"NI",IF(COUNTIF(M40:M40,"Pass")>0,"Pass","")))) | P40: 같은 버튼이 화면에 따라 다르게 동작하는 자리라 TC-DSC-001과 나눴습니다 | Q40: TC-DSC-002 | R40: 결정적 | S40: 성인 인증
B41: =ROW()-9 | C41: 전역 셸 | D41: 상단 바 | E41: 홈에서 로고 재선택 | I41: 목록이 최상단으로 스크롤된다 | J41: 공통 | K41: Low | L41: =IF(COUNTIF(M41:M41,"Fail")>0,"Fail",IF(COUNTIF(M41:M41,"Blocked")>0,"Blocked",IF(COUNTIF(M41:M41,"NI")>0,"NI",IF(COUNTIF(M41:M41,"Pass")>0,"Pass","")))) | Q41: TC-DSC-002 | R41: 결정적 | S41: 성인 인증
...

Sheet Summary
B2: 커버리지 요약
B3: Test Case 시트를 참조하는 수식으로 자동 집계됩니다. 행을 추가하면 아래 범위를 넓히세요.
B4: 기준 골격 버전 | C4: qa-lab-miyonchat-tree-v1.13
B5: 1-Depth (영역) | C5: TC 수 | D5: Priority | G5: Web
D6: High | E6: Medium | F6: Low | G6: Pass | H6: Fail | I6: Blocked | J6: Pass율
B7: 웹 진입 | C7: =COUNTIF('Test Case'!$C$10:$C$500,$B7) | D7: =COUNTIFS('Test Case'!$C$10:$C$500,$B7,'Test Case'!$K$10:$K$500,"High") | E7: =COUNTIFS('Test Case'!$C$10:$C$500,$B7,'Test Case'!$K$10:$K$500,"Medium") | F7: =COUNTIFS('Test Case'!$C$10:$C$500,$B7,'Test Case'!$K$10:$K$500,"Low") | G7: =COUNTIFS('Test Case'!$C$10:$C$500,$B7,'Test Case'!$M$10:$M$500,"Pass") | H7: =COUNTIFS('Test Case'!$C$10:$C$500,$B7,'Test Case'!$M$10:$M$500,"Fail") | I7: =COUNTIFS('Test Case'!$C$10:$C$500,$B7,'Test Case'!$M$10:$M$500,"Blocked") | J7: =IF(G7+H7=0,"",G7/(G7+H7))
B8: 전역 셸 | C8: =COUNTIF('Test Case'!$C$10:$C$500,$B8) | D8: =COUNTIFS('Test Case'!$C$10:$C$500,$B8,'Test Case'!$K$10:$K$500,"High") | E8: =COUNTIFS('Test Case'!$C$10:$C$500,$B8,'Test Case'!$K$10:$K$500,"Medium") | F8: =COUNTIFS('Test Case'!$C$10:$C$500,$B8,'Test Case'!$K$10:$K$500,"Low") | G8: =COUNTIFS('Test Case'!$C$10:$C$500,$B8,'Test Case'!$M$10:$M$500,"Pass") | H8: =COUNTIFS('Test Case'!$C$10:$C$500,$B8,'Test Case'!$M$10:$M$500,"Fail") | I8: =COUNTIFS('Test Case'!$C$10:$C$500,$B8,'Test Case'!$M$10:$M$500,"Blocked") | J8: =IF(G8+H8=0,"",G8/(G8+H8))
B9: 홈 화면 | C9: =COUNTIF('Test Case'!$C$10:$C$500,$B9) | D9: =COUNTIFS('Test Case'!$C$10:$C$500,$B9,'Test Case'!$K$10:$K$500,"High") | E9: =COUNTIFS('Test Case'!$C$10:$C$500,$B9,'Test Case'!$K$10:$K$500,"Medium") | F9: =COUNTIFS('Test Case'!$C$10:$C$500,$B9,'Test Case'!$K$10:$K$500,"Low") | G9: =COUNTIFS('Test Case'!$C$10:$C$500,$B9,'Test Case'!$M$10:$M$500,"Pass") | H9: =COUNTIFS('Test Case'!$C$10:$C$500,$B9,'Test Case'!$M$10:$M$500,"Fail") | I9: =COUNTIFS('Test Case'!$C$10:$C$500,$B9,'Test Case'!$M$10:$M$500,"Blocked") | J9: =IF(G9+H9=0,"",G9/(G9+H9))
B10: 캐릭터 페이지 | C10: =COUNTIF('Test Case'!$C$10:$C$500,$B10) | D10: =COUNTIFS('Test Case'!$C$10:$C$500,$B10,'Test Case'!$K$10:$K$500,"High") | E10: =COUNTIFS('Test Case'!$C$10:$C$500,$B10,'Test Case'!$K$10:$K$500,"Medium") | F10: =COUNTIFS('Test Case'!$C$10:$C$500,$B10,'Test Case'!$K$10:$K$500,"Low") | G10: =COUNTIFS('Test Case'!$C$10:$C$500,$B10,'Test Case'!$M$10:$M$500,"Pass") | H10: =COUNTIFS('Test Case'!$C$10:$C$500,$B10,'Test Case'!$M$10:$M$500,"Fail") | I10: =COUNTIFS('Test Case'!$C$10:$C$500,$B10,'Test Case'!$M$10:$M$500,"Blocked") | J10: =IF(G10+H10=0,"",G10/(G10+H10))
B11: 대화 프로필 화면 | C11: =COUNTIF('Test Case'!$C$10:$C$500,$B11) | D11: =COUNTIFS('Test Case'!$C$10:$C$500,$B11,'Test Case'!$K$10:$K$500,"High") | E11: =COUNTIFS('Test Case'!$C$10:$C$500,$B11,'Test Case'!$K$10:$K$500,"Medium") | F11: =COUNTIFS('Test Case'!$C$10:$C$500,$B11,'Test Case'!$K$10:$K$500,"Low") | G11: =COUNTIFS('Test Case'!$C$10:$C$500,$B11,'Test Case'!$M$10:$M$500,"Pass") | H11: =COUNTIFS('Test Case'!$C$10:$C$500,$B11,'Test Case'!$M$10:$M$500,"Fail") | I11: =COUNTIFS('Test Case'!$C$10:$C$500,$B11,'Test Case'!$M$10:$M$500,"Blocked") | J11: =IF(G11+H11=0,"",G11/(G11+H11))
B12: 대화방 | C12: =COUNTIF('Test Case'!$C$10:$C$500,$B12) | D12: =COUNTIFS('Test Case'!$C$10:$C$500,$B12,'Test Case'!$K$10:$K$500,"High") | E12: =COUNTIFS('Test Case'!$C$10:$C$500,$B12,'Test Case'!$K$10:$K$500,"Medium") | F12: =COUNTIFS('Test Case'!$C$10:$C$500,$B12,'Test Case'!$K$10:$K$500,"Low") | G12: =COUNTIFS('Test Case'!$C$10:$C$500,$B12,'Test Case'!$M$10:$M$500,"Pass") | H12: =COUNTIFS('Test Case'!$C$10:$C$500,$B12,'Test Case'!$M$10:$M$500,"Fail") | I12: =COUNTIFS('Test Case'!$C$10:$C$500,$B12,'Test Case'!$M$10:$M$500,"Blocked") | J12: =IF(G12+H12=0,"",G12/(G12+H12))
B13: 채팅 탭 | C13: =COUNTIF('Test Case'!$C$10:$C$500,$B13) | D13: =COUNTIFS('Test Case'!$C$10:$C$500,$B13,'Test Case'!$K$10:$K$500,"High") | E13: =COUNTIFS('Test Case'!$C$10:$C$500,$B13,'Test Case'!$K$10:$K$500,"Medium") | F13: =COUNTIFS('Test Case'!$C$10:$C$500,$B13,'Test Case'!$K$10:$K$500,"Low") | G13: =COUNTIFS('Test Case'!$C$10:$C$500,$B13,'Test Case'!$M$10:$M$500,"Pass") | H13: =COUNTIFS('Test Case'!$C$10:$C$500,$B13,'Test Case'!$M$10:$M$500,"Fail") | I13: =COUNTIFS('Test Case'!$C$10:$C$500,$B13,'Test Case'!$M$10:$M$500,"Blocked") | J13: =IF(G13+H13=0,"",G13/(G13+H13))
B14: MY 탭 | C14: =COUNTIF('Test Case'!$C$10:$C$500,$B14) | D14: =COUNTIFS('Test Case'!$C$10:$C$500,$B14,'Test Case'!$K$10:$K$500,"High") | E14: =COUNTIFS('Test Case'!$C$10:$C$500,$B14,'Test Case'!$K$10:$K$500,"Medium") | F14: =COUNTIFS('Test Case'!$C$10:$C$500,$B14,'Test Case'!$K$10:$K$500,"Low") | G14: =COUNTIFS('Test Case'!$C$10:$C$500,$B14,'Test Case'!$M$10:$M$500,"Pass") | H14: =COUNTIFS('Test Case'!$C$10:$C$500,$B14,'Test Case'!$M$10:$M$500,"Fail") | I14: =COUNTIFS('Test Case'!$C$10:$C$500,$B14,'Test Case'!$M$10:$M$500,"Blocked") | J14: =IF(G14+H14=0,"",G14/(G14+H14))
B15: 재화 | C15: =COUNTIF('Test Case'!$C$10:$C$500,$B15) | D15: =COUNTIFS('Test Case'!$C$10:$C$500,$B15,'Test Case'!$K$10:$K$500,"High") | E15: =COUNTIFS('Test Case'!$C$10:$C$500,$B15,'Test Case'!$K$10:$K$500,"Medium") | F15: =COUNTIFS('Test Case'!$C$10:$C$500,$B15,'Test Case'!$K$10:$K$500,"Low") | G15: =COUNTIFS('Test Case'!$C$10:$C$500,$B15,'Test Case'!$M$10:$M$500,"Pass") | H15: =COUNTIFS('Test Case'!$C$10:$C$500,$B15,'Test Case'!$M$10:$M$500,"Fail") | I15: =COUNTIFS('Test Case'!$C$10:$C$500,$B15,'Test Case'!$M$10:$M$500,"Blocked") | J15: =IF(G15+H15=0,"",G15/(G15+H15))
B16: 스텁·정적 | C16: =COUNTIF('Test Case'!$C$10:$C$500,$B16) | D16: =COUNTIFS('Test Case'!$C$10:$C$500,$B16,'Test Case'!$K$10:$K$500,"High") | E16: =COUNTIFS('Test Case'!$C$10:$C$500,$B16,'Test Case'!$K$10:$K$500,"Medium") | F16: =COUNTIFS('Test Case'!$C$10:$C$500,$B16,'Test Case'!$K$10:$K$500,"Low") | G16: =COUNTIFS('Test Case'!$C$10:$C$500,$B16,'Test Case'!$M$10:$M$500,"Pass") | H16: =COUNTIFS('Test Case'!$C$10:$C$500,$B16,'Test Case'!$M$10:$M$500,"Fail") | I16: =COUNTIFS('Test Case'!$C$10:$C$500,$B16,'Test Case'!$M$10:$M$500,"Blocked") | J16: =IF(G16+H16=0,"",G16/(G16+H16))
B17: 합계 | C17: =SUM(C7:C16) | D17: =SUM(D7:D16) | E17: =SUM(E7:E16) | F17: =SUM(F7:F16) | G17: =SUM(G7:G16) | H17: =SUM(H7:H16) | I17: =SUM(I7:I16) | J17: =IF(G17+H17=0,"",G17/(G17+H17)) | K17: =SUM(K7:K16)
B19: TC 수 = 스텝 행 수(1-Depth 기준) · Pass/Fail/Blocked도 같은 행 단위(Result 열) · Pass율 = Pass ÷ (Pass + Fail) — NI·Blocked는 분모에서 제외합니다

Sheet 이슈 관리 시트
B2: 프로젝트 ID | C2: Issue No. | D2: 이슈 상태 | E2: 요약(Summary) | F2: 설명 | G2: 우선순위 | H2: 빈도 | I2: 영향 받는 버전 | J2: 수정 버전 | K2: 해결책 | L2: 환경 | M2: 레이블 | N2: 보고자 | O2: 담당자 | P2: 관측자 | Q2: 첨부파일 | R2: 스프린트 | S2: 이슈 등록일 | T2: 이슈 최종 수정일자 | U2: 이슈 상태 최종 변경일자
B3: miyonchat | C3: miyonchat-1 | D3: Resolved | E3: 디버그 콘솔 > 전체 초기화(reset) 수행 > 계정 A 로그인 시, 성인 인증이 해제된 상태로 시작됨 | F3: Pre-condition: SUT 진입 Reproduce Step: 디버그 콘솔 열기 > [전체 초기화] 선택 > 계정 A로 로그인 > 간편 프로필 확인 Actual Result: "성인 미인증"으로 표시되고 언세이프 게이트가 열리지 않음 Expected Result: 계정 A는 기본값이 성인 인증 완료이므로 "성인 인증 완료"로 표시되어야 함 QA Comment: 계정 상태 생성 함수에 계정 식별자를 전달하지 않아 기본값 판정이 항상 거짓이 됨. 자동화가 매 테스트 전 reset()을 호출하는 구조라, 남아 있으면 게이팅 계열 TC 전체가 미인증 상태에서 실행되어 결과를 신뢰할 수 없음 | G3: High | H3: Always | I3: PC웹_Ver1.0_Dev_RC1 | J3: PC웹_Ver1.0_Dev_RC2 | K3: Fixed | L3: PC웹 | M3: 계정/게이팅 | N3: 정준호 | O3: Claude Opus 5 | R3: PC웹_Ver1.0_Dev | S3: 2026-08-02 | T3: 2026-08-02 | U3: 2026-08-02

Sheet 목록
B2: 프로젝트 | C2: 실행 주체 | D2: 상태 | E2: 이슈 상태 | F2: 우선순위 | G2: 빈도 | H2: 버전(영향/수정 공용) | I2: 해결책 | J2: 환경 | K2: 레이블 | L2: 보고자 | M2: 담당자 | N2: 스프린트
B3: miyonchat | C3: 자동화 전용 | D3: 미로그인 | E3: Open | F3: High | G3: Always | H3: PC웹_Ver1.0_Dev_RC1 | I3: Fixed | J3: PC웹 | K3: 앱 진입/세션 | L3: 정준호 | M3: Claude Opus 5 | N3: PC웹_Ver1.0_Dev
C4: 공통 | D4: 본인인증 미진행 | E4: In Progress | F4: Medium | G4: Often | H4: PC웹_Ver1.0_Dev_RC2 | I4: Won't Do | K4: 계정/게이팅 | N4: PC웹_Ver1.0_RT1
C5: 사람 전용 | D5: 성인 인증 | E5: Resolved | F5: Low | G5: Sometimes | H5: PC웹_Ver1.0_Dev_RC3 | I5: Won't Fix | K5: 탐색/발견
D6: 미성년 | E6: Reopen | G6: Once | H6: PC웹_Ver1.0_RT1_RC1 | I6: Duplicate | K6: 유저 페르소나
D7: 세션 만료 | E7: Closed | I7: Incomplete | K7: 재화
I8: Cannot Reproduce | K8: 서사 시스템
I9: Done | K9: 대화 세션
I10: Declined | K10: 세이브/로드
K11: 메모리/컨텍스트
K12: 입력/출력 세이프티

Sheet 명세서
B2: 명세서 — 시트 규칙 정본
B3: 이 시트가 구조 규칙의 정본입니다. rules/tc-sheet-format.md와 짝으로 교차 검증하며, 불일치 발견 시 임의 판단 없이 사용자에게 기준을 확인합니다. 서식(색·테두리·폰트)의 정본은 design-template/xlsx-design-guide.md입니다.
B5: 1. 시트 구성
B6: 시트 | C6: 역할
B7: Test Case | C7: TC 작성과 실행 기록. 노란 셀은 실행 단계에서 채워집니다
B8: Summary | C8: 행 단위 자동 집계(1-Depth 기준). 기준 골격 버전(C4)은 생성 시 자동 기입됩니다
B9: 이슈 관리 시트 | C9: 결함 기록(내장 운영, JIRA 미사용) — JIRA 이슈 등록·관리 방식을 시트로 표현. Issue No.로 Test Case와 연결합니다. 정본은 별도 파일 test-case/{프로젝트}-issues.json이며 이 시트는 그 파생입니다
B10: 목록 | C10: 드롭다운 참조 목록의 정본. 숨기지 않고 맨 뒤에 둡니다
B11: 명세서 | C11: 이 시트 — 구조 규칙의 정본
B13: 2. 컬럼 정의 (Test Case)
B14: 컬럼 | C14: 내용 | D14: 채우는 규칙
B15: No | C15: 행 번호 | D15: 자동 수식(ROW() 기준). 직접 입력하지 않습니다
B16: 1~7-Depth | C16: 기능 계층 | D16: 행마다 반복(기대결과 추가 행 포함 — 집계·필터의 전제). 의미 있는 깊이까지만 쓰고 나머지는 빈칸. 병합하지 않습니다
B17: Pre-Condition | C17: 사전조건 | D17: TN 1행에 케이스 진입 조건. 중간 스텝에 앞 스텝이 만들지 못하는 새 상태(시간 경과·외부 변화 등)가 필요하면 그 행에도 적습니다 — 앞 스텝의 결과로 성립한 상태는 제외. 같은 조건이 걸리는 스텝 행 범위는 세로 병합하되 케이스 전체 병합은 금지
B18: TN | C18: 스텝 번호 | D18: 케이스마다 1부터. 새 케이스가 시작되면 1로 복귀. 한 스텝의 기대결과가 여러 행이면(TN 값 무관) Test-Step과 함께 그 범위를 세로 병합합니다 — 반복 기재하면 독립 동작 여러 개로 오독됩니다
B19: Test-Step | C19: 수행 동작 | D19: 「~한다」 체. TN과 같은 범위로 세로 병합
B20: Expected-Result | C20: 기대 결과 | D20: 「~된다」 체. 판정 가능한 문장 — 임계·합격선·시도 횟수는 문장 안에 숫자로. 한 행 = 한 판정이므로 병합하지 않습니다
B21: 실행 주체 | C21: 누가 수행하는가 | D21: 행마다 반복(드롭다운 3종). 자동화 전용 = 사람이 화면만 봐서 판정 불가 / 사람 전용 = 자동화가 판정 기준을 못 세움 / 공통 = 기본값. 반복 횟수는 판정 근거가 아니며 「사람이 1회 봐도 의미가 있는가」로 갈립니다
B22: Priority | C22: 우선순위 | D22: 행마다 반복. High/Medium/Low — 케이스의 속성이지만 Summary가 행 단위로 집계하므로 행마다 값을 둡니다
B23: Total Result | C23: 행 판정 | D23: 수식 열. 병합하지 않고 데이터 한 행씩 세웁니다 — 같은 플랫폼에 단말이 여럿일 때 그 행의 단말 결과를 요약합니다. 직접 입력하지 않습니다
B24: Result | C24: 스텝 실행 결과 | D24: 드롭다운 4종(아래 상태값 정의). 실행 단계에서 채움 — 노란 셀
B25: Issue No. | C25: 관련 이슈 | D25: 해당 TC를 수행하는 과정에서 이슈가 발생하면, 먼저 이슈 관리 시트에 이슈를 등록하고 거기서 부여된 Issue No.를 이 칸에 적습니다. 실행 단계에서 채움 — 노란 셀
... B30: 상태 | C30: 케이스가 밟는 게이팅·세션 상태 (2026-08-04 신설) | D30: 행마다 반복. 값 5종은 목록 시트가 정본이고 복수 상태는 쉼표로 적습니다(전환 케이스 — 드롭다운을 걸지 않는 이유). 자동 필터를 「포함」 조건으로 걸어 상태별 TC를 추출하고, 트리의 [상태:] 선언과 맞물려 잎×상태 커버리지를 대조합니다
B32: 3. 상태값 정의
B33: 상태 | C33: 정의 | D33: Pass율 분모
B34: Pass | C34: 성공 | D34: 포함
B35: Fail | C35: 실패 | D35: 포함
B36: NI | C36: 미구현이거나 스펙에 없어 실행 대상이 아님 (Not Implemented) | D36: 제외
B37: Blocked | C37: 기능은 구현됐으나 확인할 수 없는 상태 — 선행 케이스 Fail·환경 결함·데이터 준비 불가 등. 사유는 실행 과정에서 Comment에 적습니다 | D37: 제외
B38: Pass율 = Pass ÷ (Pass + Fail). NI·Blocked를 분모에 넣지 않는 이유는 결함 1건이 후속 Blocked 수만큼 중복 계상되는 것을 막기 위해서입니다.
B40: 4. Total Result 규칙
B41: 항목 | C41: 규칙
B42: 우선순위 | C42: Fail > Blocked > NI > Pass — 스텝 중 하나라도 Fail이면 케이스 Fail
B43: 수식 원형 | C43: IF(COUNTIF(범위,"Fail")>0,"Fail",IF(COUNTIF(범위,"Blocked")>0,"Blocked",IF(COUNTIF(범위,"NI")>0,"NI",IF(COUNTIF(범위,"Pass")>0,"Pass","")))) — 셀에는 앞에 = 를 붙여 사용합니다. 아무것도 실행되지 않은 케이스는 빈칸입니다
B44: 병합 | C44: 하지 않습니다 — 데이터 한 행씩 세웁니다. 같은 플랫폼에 단말이 여럿일 때 그 행의 단말 결과를 하나로 요약하는 자리입니다
B46: 5. TC ID 체계
B47: 항목 | C47: 규칙
B48: 형식 | C48: TC-{영역코드}-{번호 3자리} — 예: TC-ENT-001
B49: 번호 | C49: 영역 안에서만 증가합니다. 다른 영역에 케이스가 추가돼도 기존 ID가 흔들리지 않습니다
B50: 영역코드 | C50: 기능 트리 1-Depth당 하나. 프로젝트별 매핑표는 아래 §5-1이며, 정의가 없는 프로젝트에서는 그 절이 나오지 않습니다
...
