Workbook
Name list_project: 목록!$B$3:$B$3
Name list_status: 목록!$C$3:$C$7
Name list_priority: 목록!$D$3:$D$5
Name list_frequency: 목록!$E$3:$E$6
Name list_version: 목록!$F$3:$F$3
Name list_resolution: 목록!$G$3:$G$10
Name list_env: 목록!$H$3:$H$5
Name list_label: 목록!$I$3:$I$3
Name list_reporter: 목록!$J$3:$J$3
Name list_assignee: 목록!$K$3:$K$3
Name list_sprint: 목록!$L$3:$L$3

Sheet Test Case
B3: Test Case Template
B4: No | C4: 1-Depth | D4: 2-Depth | E4: 3-Depth | F4: 4-Depth | G4: 5-Depth | H4: 6-Depth | I4: 7-Depth | J4: Pre-Condition | K4: TN | L4: Test-Step | M4: Expected-Result | N4: Priority | O4: Total Result | R4: Result | U4: Issue No. | V4: Comment | W4: Note | X4: Test Case Edit
O5: Web | P5: And | Q5: iOS | R5: Web | S5: And | T5: iOS
N6: OS | V6: ※ 노란색 셀은 실행 단계에서 채워집니다 — 환경 정보 / Result / Issue No. / Comment · 수행 전 참고사항은 전부 Note에 있습니다
N7: 단말 | R7: Chrome / Safari
N8: 버전 | V8: ※ 1-Depth는 기능 영역 기준. 실제 탐색으로 화면명이 확정되면 1-Depth에 화면명을 넣고 현재 계층을 한 칸씩 내림
N9: 작업자 이름
N10: 작업 시작일
B11: =ROW()-10 | C11: 앱 진입 | D11: 최초 실행 | E11: 진입 분기 | F11: 미로그인 최초 실행 | J11: 앱 최초 설치, 로그인 이력 없음 | K11: 1 | L11: 앱을 실행한다 | M11: 앱이 정상 기동된다 | N11: High | O11: =IF(COUNTIF(R11:R12,"Fail")>0,"Fail",IF(COUNTIF(R11:R12,"Blocked")>0,"Blocked",IF(COUNTIF(R11:R12,"NI")>0,"NI",IF(COUNTIF(R11:R12,"Pass")>0,"Pass","")))) | P11: =IF(COUNTIF(S11:S12,"Fail")>0,"Fail",IF(COUNTIF(S11:S12,"Blocked")>0,"Blocked",IF(COUNTIF(S11:S12,"NI")>0,"NI",IF(COUNTIF(S11:S12,"Pass")>0,"Pass","")))) | Q11: =IF(COUNTIF(T11:T12,"Fail")>0,"Fail",IF(COUNTIF(T11:T12,"Blocked")>0,"Blocked",IF(COUNTIF(T11:T12,"NI")>0,"NI",IF(COUNTIF(T11:T12,"Pass")>0,"Pass","")))) | W11: TC-ENT-001 · 1단계 · 선행 - · 대상 {서비스명} 결정적 · 1회 실행, 기대값 불일치 시 FAIL
B12: =ROW()-10 | C12: 앱 진입 | D12: 최초 실행 | E12: 진입 분기 | F12: 미로그인 최초 실행 | K12: 2 | L12: 노출 화면을 확인한다 | M12: 로그인 화면이 노출된다 | N12: High
B13: =ROW()-10 | C13: 앱 진입 | D13: 최초 실행 | E13: 진입 분기 | F13: 세션 유지 상태 실행 | J13: 로그인 이력 있음, 세션 유효 | K13: 1 | L13: 앱을 실행한다 | M13: 앱이 정상 기동된다 | N13: High | O13: =IF(COUNTIF(R13:R14,"Fail")>0,"Fail",IF(COUNTIF(R13:R14,"Blocked")>0,"Blocked",IF(COUNTIF(R13:R14,"NI")>0,"NI",IF(COUNTIF(R13:R14,"Pass")>0,"Pass","")))) | P13: =IF(COUNTIF(S13:S14,"Fail")>0,"Fail",IF(COUNTIF(S13:S14,"Blocked")>0,"Blocked",IF(COUNTIF(S13:S14,"NI")>0,"NI",IF(COUNTIF(S13:S14,"Pass")>0,"Pass","")))) | Q13: =IF(COUNTIF(T13:T14,"Fail")>0,"Fail",IF(COUNTIF(T13:T14,"Blocked")>0,"Blocked",IF(COUNTIF(T13:T14,"NI")>0,"NI",IF(COUNTIF(T13:T14,"Pass")>0,"Pass","")))) | W13: TC-ENT-002 · 2단계 · 선행 TC-ENT-001 · 대상 {서비스명} 결정적 · 1회 실행, 기대값 불일치 시 FAIL
B14: =ROW()-10 | C14: 앱 진입 | D14: 최초 실행 | E14: 진입 분기 | F14: 세션 유지 상태 실행 | K14: 2 | L14: 노출 화면을 확인한다 | M14: 로그인 화면을 거치지 않고 홈 화면이 노출된다 | N14: High

Sheet Summary
B2: 커버리지 요약
B3: Test Case 시트를 참조하는 수식으로 자동 집계됩니다. 행을 추가하면 아래 범위를 넓히세요.
B4: 기준 골격 버전 | C4: {프로젝트}-tree-vX.Y
B5: 1-Depth (영역) | C5: TC 수 | D5: Priority | G5: Web | K5: And | O5: iOS
D6: High | E6: Medium | F6: Low | G6: Pass | H6: Fail | I6: Blocked | J6: Pass율 | K6: Pass | L6: Fail | M6: Blocked | N6: Pass율 | O6: Pass | P6: Fail | Q6: Blocked | R6: Pass율
B7: 앱 진입 | C7: =COUNTIF('Test Case'!$C$11:$C$500,$B7) | D7: =COUNTIFS('Test Case'!$C$11:$C$500,$B7,'Test Case'!$N$11:$N$500,"High") | E7: =COUNTIFS('Test Case'!$C$11:$C$500,$B7,'Test Case'!$N$11:$N$500,"Medium") | F7: =COUNTIFS('Test Case'!$C$11:$C$500,$B7,'Test Case'!$N$11:$N$500,"Low") | G7: =COUNTIFS('Test Case'!$C$11:$C$500,$B7,'Test Case'!$R$11:$R$500,"Pass") | H7: =COUNTIFS('Test Case'!$C$11:$C$500,$B7,'Test Case'!$R$11:$R$500,"Fail") | I7: =COUNTIFS('Test Case'!$C$11:$C$500,$B7,'Test Case'!$R$11:$R$500,"Blocked") | J7: =IF(G7+H7=0,"",G7/(G7+H7)) | K7: =COUNTIFS('Test Case'!$C$11:$C$500,$B7,'Test Case'!$S$11:$S$500,"Pass") | L7: =COUNTIFS('Test Case'!$C$11:$C$500,$B7,'Test Case'!$S$11:$S$500,"Fail") | M7: =COUNTIFS('Test Case'!$C$11:$C$500,$B7,'Test Case'!$S$11:$S$500,"Blocked") | N7: =IF(K7+L7=0,"",K7/(K7+L7)) | O7: =COUNTIFS('Test Case'!$C$11:$C$500,$B7,'Test Case'!$T$11:$T$500,"Pass") | P7: =COUNTIFS('Test Case'!$C$11:$C$500,$B7,'Test Case'!$T$11:$T$500,"Fail") | Q7: =COUNTIFS('Test Case'!$C$11:$C$500,$B7,'Test Case'!$T$11:$T$500,"Blocked") | R7: =IF(O7+P7=0,"",O7/(O7+P7))
B8: 합계 | C8: =SUM(C7:C7) | D8: =SUM(D7:D7) | E8: =SUM(E7:E7) | F8: =SUM(F7:F7) | G8: =SUM(G7:G7) | H8: =SUM(H7:H7) | I8: =SUM(I7:I7) | J8: =IF(G8+H8=0,"",G8/(G8+H8)) | K8: =SUM(K7:K7) | L8: =SUM(L7:L7) | M8: =SUM(M7:M7) | N8: =IF(K8+L8=0,"",K8/(K8+L8)) | O8: =SUM(O7:O7) | P8: =SUM(P7:P7) | Q8: =SUM(Q7:Q7) | R8: =IF(O8+P8=0,"",O8/(O8+P8)) | S8: =SUM(S7:S7)
B10: TC 수 = 스텝 행 수(1-Depth 기준) · Pass/Fail/Blocked도 같은 행 단위(Result 열) · Pass율 = Pass ÷ (Pass + Fail) — NI·Blocked는 분모에서 제외합니다

Sheet 이슈 관리 시트
B2: 프로젝트 ID | C2: Issue No. | D2: 이슈 상태 | E2: 요약(Summary) | F2: 설명 | G2: 우선순위 | H2: 빈도 | I2: 영향 받는 버전 | J2: 수정 버전 | K2: 해결책 | L2: 환경 | M2: 레이블 | N2: 보고자 | O2: 담당자 | P2: 관측자 | Q2: 첨부파일 | R2: 스프린트 | S2: 이슈 등록일 | T2: 이슈 최종 수정일자 | U2: 이슈 상태 최종 변경일자
B3: {프로젝트} | C3: {프로젝트}-1 | D3: Open | E3: {화면} 진입 > {동작} 시, {결과} 안 됨 | F3: Pre-condition: {사전 조건} Reproduce Step: {재현 스텝} Actual Result: {실제 결과} Expected Result: {기대 결과} QA Comment: {참고} | G3: High | H3: Always | L3: PC웹 | S3: YYYY-MM-DD | T3: YYYY-MM-DD | U3: YYYY-MM-DD

Sheet 목록
B2: 프로젝트 | C2: 이슈 상태 | D2: 우선순위 | E2: 빈도 | F2: 버전(영향/수정 공용) | G2: 해결책 | H2: 환경 | I2: 레이블 | J2: 보고자 | K2: 담당자 | L2: 스프린트
B3: {프로젝트} | C3: Open | D3: High | E3: Always | F3: {디바이스}_{QA프로젝트}_RC1 | G3: Fixed | H3: PC웹 | I3: {기능 트리 1-Depth 영역명} | J3: {작성자} | K3: {담당자} | L3: {QA 프로젝트명}
C4: In Progress | D4: Medium | E4: Often | G4: Won't Do | H4: Android
C5: Resolved | D5: Low | E5: Sometimes | G5: Won't Fix | H5: iOS
C6: Reopen | E6: Once | G6: Duplicate
C7: Closed | G7: Incomplete
G8: Cannot Reproduce
G9: Done
G10: Declined

Sheet 명세서
B2: 명세서 — 시트 규칙 정본
B3: 이 시트가 구조 규칙의 정본입니다. rules/tc-sheet-format.md와 짝으로 교차 검증하며, 불일치 발견 시 임의 판단 없이 사용자에게 기준을 확인합니다. 서식(색·테두리·폰트)의 정본은 design-template/xlsx-design-guide.md입니다.
B5: 1. 시트 구성
B6: 시트 | C6: 역할
B7: Test Case | C7: TC 작성과 실행 기록. 노란 셀은 실행 단계에서 채워집니다
B8: Summary | C8: 행 단위 자동 집계(1-Depth 기준). 기준 골격 버전(C4)은 생성 시 자동 기입됩니다
B9: 이슈 관리 시트 | C9: 결함 기록(내장 운영, JIRA 미사용) — JIRA 이슈 등록·관리 방식을 시트로 표현. Issue No.로 Test Case와 연결합니다. 정본은 별도 파일 test-case/{프로젝트}-issues.json이며 이 시트는 그 파생입니다
B10: 목록 | C10: 드롭다운 참조 목록의 정본. 숨기지 않고 맨 뒤에 둡니다
B11: 명세서 | C11: 이 시트 — 구조 규칙의 정본
B13: 2. 컬럼 정의 (Test Case)
B14: 컬럼 | C14: 내용 | D14: 채우는 규칙
B15: No | C15: 행 번호 | D15: 자동(ROW()-10). 직접 입력하지 않습니다
B16: 1~7-Depth | C16: 기능 계층 | D16: 스텝 행마다 반복. 의미 있는 깊이까지만 쓰고 나머지는 빈칸
B17: Pre-Condition | C17: 사전조건 | D17: TN 1행에 케이스 진입 조건. 중간 스텝에 앞 스텝이 만들지 못하는 새 상태(시간 경과·외부 변화 등)가 필요하면 그 행에도 적습니다 — 앞 스텝의 결과로 성립한 상태는 제외
B18: TN | C18: 스텝 번호 | D18: 케이스마다 1부터. 새 케이스가 시작되면 1로 복귀
B19: Test-Step | C19: 수행 동작 | D19: 「~한다」 체
B20: Expected-Result | C20: 기대 결과 | D20: 「~된다」 체. 판정 가능한 문장 — 임계·합격선·시도 횟수는 문장 안에 숫자로
B21: Priority | C21: 우선순위 | D21: 스텝 행마다 반복. High/Medium/Low — 케이스의 속성이지만 Summary가 행 단위로 집계하므로 행마다 값을 둡니다
B22: Total Result | C22: 케이스 판정 | D22: 수식 열. 케이스 행 범위를 세로 병합하며 직접 입력하지 않습니다
B23: Result | C23: 스텝 실행 결과 | D23: 드롭다운 4종(아래 상태값 정의). 실행 단계에서 채움 — 노란 셀
B24: Issue No. | C24: 이슈 연결 | D24: 이슈 관리 시트의 Issue No. 실행 단계에서 채움 — 노란 셀
B25: Comment | C25: 수행 중 기록 | D25: TC를 수행하다 생긴 문제·관찰을 실행 단계에서 적습니다 — 노란 셀. 설계 시점에는 비어 있습니다
... B27: Test Case Edit | C27: 편집 이력 | D27: 자유 기재
B29: 3. 상태값 정의
B30: 상태 | C30: 정의 | D30: Pass율 분모
B31: Pass | C31: 성공 | D31: 포함
B32: Fail | C32: 실패 | D32: 포함
B33: NI | C33: 미구현이거나 스펙에 없어 실행 대상이 아님 (Not Implemented) | D33: 제외
B34: Blocked | C34: 기능은 구현됐으나 선행 TC의 Fail로 확인 불가 | D34: 제외
B35: Pass율 = Pass ÷ (Pass + Fail). NI·Blocked를 분모에 넣지 않는 이유는 결함 1건이 후속 Blocked 수만큼 중복 계상되는 것을 막기 위해서입니다.
B37: 4. Total Result 규칙
B38: 항목 | C38: 규칙
B39: 우선순위 | C39: Fail > Blocked > NI > Pass — 스텝 중 하나라도 Fail이면 케이스 Fail
B40: 수식 원형 | C40: IF(COUNTIF(범위,"Fail")>0,"Fail",IF(COUNTIF(범위,"Blocked")>0,"Blocked",IF(COUNTIF(범위,"NI")>0,"NI",IF(COUNTIF(범위,"Pass")>0,"Pass","")))) — 셀에는 앞에 = 를 붙여 사용합니다. 아무것도 실행되지 않은 케이스는 빈칸입니다
B41: 병합 | C41: 케이스의 스텝 행 범위를 플랫폼 열마다 세로 병합
B43: 5. TC ID 체계
B44: 항목 | C44: 규칙
B45: 형식 | C45: TC-{영역코드}-{번호 3자리} — 예: TC-ENT-001
B46: 번호 | C46: 영역 안에서만 증가합니다. 다른 영역에 케이스가 추가돼도 기존 ID가 흔들리지 않습니다
B47: 영역코드 | C47: 기능 트리 1-Depth당 하나. 매핑표는 프로젝트 시트에서 정의합니다 (예: 앱 진입=ENT)
...
